Workbook

Sheet SECAP2030 mērķi
A1: Rīgas SECAP 2022–2030: enerģētikas un CO2 emisiju mērķi
A2: Avots: Rīgas pilsētas Ilgtspējīgas enerģētikas un klimata rīcības plāns 2022.–2030. gadam
A4: 4.1. tabula: Enerģētikas mērķi Rīgas pilsētai līdz 2030. gadam
A5: Mērķis | B5: Mērķa vērtība | C5: Mērķa gads | D5: Bāzes vērtība | E5: Bāzes gads | F5: Vidusposma statuss - 2025. gads | G5: 2025. gada vērtība | H5: Progress līdz mērķim | I5: Rādītājs / komentārs | J5: Bāze (aprēķinam) | K5: Mērķis (aprēķinam) | L5: Laika progress (aprēķinam)
A6: Pašvaldības infrastruktūra un iekārtas
A7: Ieviest, uzturēt un sertificēt EPS pašvaldībā atbilstoši ISO 50001:2018 standartam | B7: Sertifikāts | C7: 2022 | D7: Nav | E7: 2020 | F7: Sasniegts | G7: ='Rādītāji - vērtības'!M8 -> 424 | I7: Rādītājs 1001: objektu skaits energopārvaldības sistēmā.
A8: Samazināt enerģijas patēriņu pašvaldības ēkās | B8: -20% | C8: 2030 | D8: 199 243 MWh | E8: 2019 | F8: =IF(H8="","Nav datu",IF(H8>=1,"Sasniegts",IF(H8>=L8-$B$45,"Atbilst trajektorijai",IF(H8>0,"Atpaliek no trajektorijas","Nav progresa")))) -> Atbilst trajektorijai | G8: ='Rādītāji - vērtības'!M9 -> 171992 | H8: =IF(OR(G8="",J8="",K8=""),"",(G8-J8)/(K8-J8)) -> 0.68386342 | I8: Rādītājs 1002 (elektroenerģija + siltumenerģija, bez dabasgāzes – kā SECAP bāzē). | J8: 199243 | K8: =J8*(1-20%) -> 159394.4 | L8: =IFERROR(($B$40-VALUE(LEFT(E8,4)))/($B$41-VALUE(LEFT(E8,4))),$B$43) -> 0.54545455
A9: Nodrošināt klimatneitralitāti pašvaldības ēkās attiecībā uz izmantoto siltumenerģiju | B9: 100% AER | C9: 2030 | D9: 31% | E9: 2019 | F9: =IF(H9="","Nav datu",IF(H9>=1,"Sasniegts",IF(H9>=L9-$B$45,"Atbilst trajektorijai",IF(H9>0,"Atpaliek no trajektorijas","Nav progresa")))) -> Atpaliek no trajektorijas | G9: ='Rādītāji - vērtības'!M40 -> 0.4685 | H9: =IF(OR(G9="",J9="",K9=""),"",(G9-J9)/(K9-J9)) -> 0.22971014 | I9: Netiešs: AER īpatsvars Rīgas CSS (rādītājs 3002), jo pašvaldības ēkas pārsvarā pieslēgtas CSS. Tiešu datu par ēku AER siltumu nav. | J9: 0.31 | K9: 1 | L9: =IFERROR(($B$40-VALUE(LEFT(E9,4)))/($B$41-VALUE(LEFT(E9,4))),$B$43) -> 0.54545455
A10: Paaugstināt AER elektroenerģijas īpatsvaru pašvaldības infrastruktūrā | B10: 100% | C10: 2030 | D10: 54,36% | E10: 2019 | F10: =IF(H10="","Nav datu",IF(H10>=1,"Sasniegts",IF(H10>=L10-$B$45,"Atbilst trajektorijai",IF(H10>0,"Atpaliek no trajektorijas","Nav progresa")))) -> Atpaliek no trajektorijas | G10: ='Rādītāji - vērtības'!M78 -> 0.576 | H10: =IF(OR(G10="",J10="",K10=""),"",(G10-J10)/(K10-J10)) -> 0.070990359 | I10: ="Netiešs: AER īpatsvars elektroenerģijā Latvijā (Eurostat RES-E; palīgdati 'Rādītāji - vērtības' rindā 78; 2025 – provizoriski). Pašvaldība izmanto tīkla elektroenerģiju; bāzes 54,36% atbilst valsts līmeņa rādītājam. Pašvaldības ēkās kopā uzstādīti "&SUBSTITUTE(TEXT('Rādītāji - vērtības'!M17,"0.0"),".",",")&" kWp saules paneļu (rādītājs 1010, kumulatīvi līdz 2025)." -> Netiešs: AER īpatsvars elektroenerģijā Latvijā (Eurostat RES-E; palīgdati 'Rādītāji - vērtības' rindā 78; 2025 – provizoriski). Pašvaldība izmanto tīkla elektroenerģiju; bāzes 54,36% atbilst valsts līmeņa rādītājam. Pašvaldības ēkās kopā uzstādīti 659,3 kWp saules paneļu (rādītājs 1010, kumulatīvi līdz 2025). | J10: 0.5436 | K10: 1 | L10: =IFERROR(($B$40-VALUE(LEFT(E10,4)))/($B$41-VALUE(LEFT(E10,4))),$B$43) -> 0.54545455
A11: Samazināt vidējo īpatnējo elektroenerģijas patēriņu, MWh/gaismeklis | B11: 0,300 | C11: 2030 | D11: 0,497 (0,597) | E11: 2020 | F11: =IF(H11="","Nav datu",IF(H11>=1,"Sasniegts",IF(H11>=L11-$B$45,"Atbilst trajektorijai",IF(H11>0,"Atpaliek no trajektorijas","Nav progresa")))) -> Atbilst trajektorijai | G11: ='Rādītāji - vērtības'!M19 -> 0.39222811 | H11: =IF(OR(G11="",J11="",K11=""),"",(G11-J11)/(K11-J11)) -> 0.53183703 | I11: Rādītājs 1012. Bāze koriģēta uz 0,497 (2020), jo gaismekļu skaits bija lielāks; SECAP bāze 0,597 (2019). | J11: 0.497 | K11: 0.3 | L11: =IFERROR(($B$40-VALUE(LEFT(E11,4)))/($B$41-VALUE(LEFT(E11,4))),$B$43) -> 0.5
A12: Samazināt vidējo īpatnējo elektroenerģijas patēriņu, MWh/luksofors | B12: 2,300 | C12: 2024 | D12: 2,314 | E12: 2019 | F12: =IF(H12="","Nav datu",IF(H12>=1,"Sasniegts",IF(H12>=L12-$B$45,"Atbilst trajektorijai",IF(H12>0,"Atpaliek no trajektorijas","Nav progresa")))) -> Nav datu | H12: =IF(OR(G12="",J12="",K12=""),"",(G12-J12)/(K12-J12)) | I12: Nav datu par luksoforu patēriņu (mērķa gads 2024). | L12: =IFERROR(($B$40-VALUE(LEFT(E12,4)))/($B$41-VALUE(LEFT(E12,4))),$B$43) -> 0.54545455
A13: Paaugstināt atjaunīgās elektroenerģijas īpatsvaru izmantošanā ielu apgaismojuma, luksoforu un pulksteņu darbināšanai | B13: 100% AER | C13: 2030 | D13: 54,36% | E13: 2019 | F13: =IF(H13="","Nav datu",IF(H13>=1,"Sasniegts",IF(H13>=L13-$B$45,"Atbilst trajektorijai",IF(H13>0,"Atpaliek no trajektorijas","Nav progresa")))) -> Atpaliek no trajektorijas | G13: ='Rādītāji - vērtības'!M78 -> 0.576 | H13: =IF(OR(G13="",J13="",K13=""),"",(G13-J13)/(K13-J13)) -> 0.070990359 | I13: Netiešs: AER īpatsvars elektroenerģijā Latvijā (Eurostat RES-E; palīgdati 'Rādītāji - vērtības' rindā 78; 2025 – provizoriski). Nav datu par AER elektroenerģijas iepirkumu ielu apgaismojumam. | J13: 0.5436 | K13: 1 | L13: =IFERROR(($B$40-VALUE(LEFT(E13,4)))/($B$41-VALUE(LEFT(E13,4))),$B$43) -> 0.54545455
A14: Paaugstināt AER īpatsvaru izmantotajā enerģijā pašvaldības darbinieku transportā | B14: 100% | C14: 2030 | D14: 1% | E14: 2019 | F14: =IF(H14="","Nav datu",IF(H14>=1,"Sasniegts",IF(H14>=L14-$B$45,"Atbilst trajektorijai",IF(H14>0,"Atpaliek no trajektorijas","Nav progresa")))) -> Atpaliek no trajektorijas | G14: ='Rādītāji - vērtības'!M22 -> 0.11988912 | H14: =IF(OR(G14="",J14="",K14=""),"",(G14-J14)/(K14-J14)) -> 0.11099911 | I14: Netiešs: elektroauto īpatsvars pašvaldības autoparkā (rādītājs 1015): 2025 – 173 no 1443 transportlīdzekļiem (12,0%); 2023 – 4,2%, 2024 – 7,8%. | J14: 0.01 | K14: 1 | L14: =IFERROR(($B$40-VALUE(LEFT(E14,4)))/($B$41-VALUE(LEFT(E14,4))),$B$43) -> 0.54545455
A15: Daudzdzīvokļu ēkas
A16: Atjaunot daudzdzīvokļu ēku dzīvojamo fondu Rīgā | B16: 2000 ēkas | C16: 2030 | D16: 159 ēkas | E16: 2019 | F16: =IF(H16="","Nav datu",IF(H16>=1,"Sasniegts",IF(H16>=L16-$B$45,"Atbilst trajektorijai",IF(H16>0,"Atpaliek no trajektorijas","Nav progresa")))) -> Atpaliek no trajektorijas | G16: ='Rādītāji - vērtības'!M33 -> 209 | H16: =IF(OR(G16="",J16="",K16=""),"",(G16-J16)/(K16-J16)) -> 0.027159153 | I16: Rādītājs 2004 (kopā atjaunotās ēkas). 2025. g. vērtība 209 un bāze 159 – Ekonomikas ministrijas dati (viena uzskaites metode); nav salīdzināmi ar 2020–2024 vērtībām rādītāju tabulā (68–146, cita uzskaite). | J16: 159 | K16: 2000 | L16: =IFERROR(($B$40-VALUE(LEFT(E16,4)))/($B$41-VALUE(LEFT(E16,4))),$B$43) -> 0.54545455
A17: Samazināt siltumenerģijas patēriņu daudzdzīvokļu ēkās, kas pieslēgtas Rīgas pilsētas CSS | B17: -20% | C17: 2030 | D17: =SUBSTITUTE(TEXT(J17/1000,"#,##0"),","," ")&" tūkst. MWh (2123 tūkst. MWh)" -> 2 456 tūkst. MWh (2123 tūkst. MWh) | E17: 2020 | F17: =IF(H17="","Nav datu",IF(H17>=1,"Sasniegts",IF(H17>=L17-$B$45,"Atbilst trajektorijai",IF(H17>0,"Atpaliek no trajektorijas","Nav progresa")))) -> Atbilst trajektorijai | G17: ='Rādītāji - vērtības'!M30 -> 2245623 | H17: =IF(OR(G17="",J17="",K17=""),"",(G17-J17)/(K17-J17)) -> 0.42767572 | I17: ="Rādītājs 2001 (siltumenerģijas patēriņš ar klimata korekciju). Bāze pārrēķināta ar klimata korekciju: "&SUBSTITUTE(TEXT(J17,"#,##0"),","," ")&" MWh (iepriekš 2123 tūkst. MWh bez korekcijas). 2025. g. patēriņš – "&SUBSTITUTE(TEXT(G17,"#,##0"),","," ")&" MWh ("&SUBSTITUTE(TEXT(G17/J17-1,"0.0%"),".",",")&" pret bāzi; mērķis −20%). Īpatnējais patēriņš (rādītājs 2002) samazinājies no "&TEXT('Rādītāji - vērtības'!H31,"0")&" līdz "&TEXT('Rādītāji - vērtības'!M31,"0")&" kWh/m2." -> Rādītājs 2001 (siltumenerģijas patēriņš ar klimata korekciju). Bāze pārrēķināta ar klimata korekciju: 2 455 669 MWh (iepriekš 2123 tūkst. MWh bez korekcijas). 2025. g. patēriņš – 2 245 623 MWh (-8,6% pret bāzi; mērķis −20%). Īpatnējais patēriņš (rādītājs 2002) samazinājies no 147 līdz 113 kWh/m2. | J17: ='Rādītāji - vērtības'!H30 -> 2455669 | K17: =J17*(1-20%) -> 1964535.2 | L17: =IFERROR(($B$40-VALUE(LEFT(E17,4)))/($B$41-VALUE(LEFT(E17,4))),$B$43) -> 0.5
A18: Centralizētā siltumapgāde
A19: Paaugstināt AER īpatsvaru Rīgas pilsētas CSS | B19: ≥66% | C19: 2030 | D19: 31% | E19: 2019 | F19: =IF(H19="","Nav datu",IF(H19>=1,"Sasniegts",IF(H19>=L19-$B$45,"Atbilst trajektorijai",IF(H19>0,"Atpaliek no trajektorijas","Nav progresa")))) -> Atbilst trajektorijai | G19: ='Rādītāji - vērtības'!M40 -> 0.4685 | H19: =IF(OR(G19="",J19="",K19=""),"",(G19-J19)/(K19-J19)) -> 0.45285714 | I19: Rādītājs 3002. | J19: 0.31 | K19: 0.66 | L19: =IFERROR(($B$40-VALUE(LEFT(E19,4)))/($B$41-VALUE(LEFT(E19,4))),$B$43) -> 0.54545455
A20: Samazināt relatīvos siltumenerģijas zudumus siltumtīklos | B20: 11,6% | C20: 2030 | D20: 11,7% | E20: 2019 | F20: Netiek vērtēts | G20: 0.1249 | H20: n/a | I20: AS "Rīgas siltums" Ilgtspējas pārskats: zudumi 12,49% – virs bāzes (11,7%) un mērķa (11,6%). Relatīvie zudumi katru gadu ir atkarīgi no klimatiskajiem apstākļiem (āra temperatūra, apkures sezonas ilgums), tāpēc gadu vērtības nav tieši salīdzināmas. Jāpārskata mērķis. | J20: 0.117 | K20: 0.116
A21: Decentralizētā siltumapgāde / gāzes apgāde
A22: Samazināt decentralizētās siltumapgādes īpatsvaru | B22: 40% | C22: 2030 | D22: =SUBSTITUTE(TEXT(J22*100,"0.0"),".",",")&"% (44%)" -> 49,9% (44%) | E22: 2020 | F22: =IF(H22="","Nav datu",IF(H22>=1,"Sasniegts",IF(H22>=L22-$B$45,"Atbilst trajektorijai",IF(H22>0,"Atpaliek no trajektorijas","Nav progresa")))) -> Atbilst trajektorijai | G22: ='Rādītāji - vērtības'!M44 -> 0.4272 | H22: =IF(OR(G22="",J22="",K22=""),"",(G22-J22)/(K22-J22)) -> 0.72441743 | I22: ="Rādītājs 3006 (decentralizētā kurināmā patēriņš / kopējais siltumenerģijas galapatēriņš; SEG inventarizācija, Kopā_2025 rinda 67 / rinda 24). 2025. g. – "&SUBSTITUTE(TEXT(G22*100,"0.0"),".",",")&"%. Bāze atšķiras no SECAP: SECAP bāzi 44% (2019) nevar atkārtot ar inventarizācijas datiem, tāpēc progress mērīts pret 2020. g. vērtību, kas aprēķināta pēc tās pašas metodes ("&SUBSTITUTE(TEXT(J22*100,"0.0"),".",",")&"%). Mērķis 40% nav mainīts." -> Rādītājs 3006 (decentralizētā kurināmā patēriņš / kopējais siltumenerģijas galapatēriņš; SEG inventarizācija, Kopā_2025 rinda 67 / rinda 24). 2025. g. – 42,7%. Bāze atšķiras no SECAP: SECAP bāzi 44% (2019) nevar atkārtot ar inventarizācijas datiem, tāpēc progress mērīts pret 2020. g. vērtību, kas aprēķināta pēc tās pašas metodes (49,9%). Mērķis 40% nav mainīts. | J22: ='Rādītāji - vērtības'!H44 -> 0.4987 | K22: 0.4 | L22: =IFERROR(($B$40-VALUE(LEFT(E22,4)))/($B$41-VALUE(LEFT(E22,4))),$B$43) -> 0.5
A23: Paaugstināt AER īpatsvaru decentralizētajā siltumapgādē Rīgas pilsētā | B23: 60% | C23: 2030 | D23: =SUBSTITUTE(TEXT(J23*100,"0.0"),".",",")&"% (42%)" -> 41,8% (42%) | E23: 2020 | F23: =IF(H23="","Nav datu",IF(H23>=1,"Sasniegts",IF(H23>=L23-$B$45,"Atbilst trajektorijai",IF(H23>0,"Atpaliek no trajektorijas","Nav progresa")))) -> Nav progresa | G23: ='Rādītāji - vērtības'!M45 -> 0.3423 | H23: =IF(OR(G23="",J23="",K23=""),"",(G23-J23)/(K23-J23)) -> -0.41749175 | I23: ="Rādītājs 3007 (AER – biomasa ārpus CSS un mājsaimniecību AER – īpatsvars decentralizētā kurināmā patēriņā; SEG inventarizācija). 2025. g. – "&SUBSTITUTE(TEXT(G23*100,"0.0"),".",",")&"%. Bāze atšķiras no SECAP: progress mērīts pret 2020. g. vērtību pēc inventarizācijas ("&SUBSTITUTE(TEXT(J23*100,"0.0"),".",",")&"%; SECAP 42%, 2019). Gada vērtības svārstās (34–43%), jo mainās biomasas sadalījums starp CSS un decentralizēto apgādi." -> Rādītājs 3007 (AER – biomasa ārpus CSS un mājsaimniecību AER – īpatsvars decentralizētā kurināmā patēriņā; SEG inventarizācija). 2025. g. – 34,2%. Bāze atšķiras no SECAP: progress mērīts pret 2020. g. vērtību pēc inventarizācijas (41,8%; SECAP 42%, 2019). Gada vērtības svārstās (34–43%), jo mainās biomasas sadalījums starp CSS un decentralizēto apgādi. | J23: ='Rādītāji - vērtības'!H45 -> 0.4182 | K23: 0.6 | L23: =IFERROR(($B$40-VALUE(LEFT(E23,4)))/($B$41-VALUE(LEFT(E23,4))),$B$43) -> 0.5
A24: Samazināt dabas gāzes patēriņu Rīgā visos sektoros | B24: -30% | C24: 2030 | D24: 362 429 tūkst. m3 | E24: 2020 | F24: =IF(H24="","Nav datu",IF(H24>=1,"Sasniegts",IF(H24>=L24-$B$45,"Atbilst trajektorijai",IF(H24>0,"Atpaliek no trajektorijas","Nav progresa")))) -> Atbilst trajektorijai | G24: ='Rādītāji - vērtības'!M43 -> 2516.877 | H24: =IF(OR(G24="",J24="",K24=""),"",(G24-J24)/(K24-J24)) -> 0.90929693 | I24: Rādītājs 3005, GWh. SECAP bāzes vērtība 362 429 tūkst. m3 atbilst GASO 2020. gada datiem (30 856 + 331 573), tāpēc salīdzināts ar 2020. gadu. | J24: ='Rādītāji - vērtības'!H43 -> 3461 | K24: =J24*(1-30%) -> 2422.7 | L24: =IFERROR(($B$40-VALUE(LEFT(E24,4)))/($B$41-VALUE(LEFT(E24,4))),$B$43) -> 0.5
A25: Elektroapgāde
A26: Paaugstināt AER elektroenerģijas īpatsvaru Rīgā | B26: >15% | C26: 2030 | D26: 4% | E26: 2019 | F26: =IF(H26="","Nav datu",IF(H26>=1,"Sasniegts",IF(H26>=L26-$B$45,"Atbilst trajektorijai",IF(H26>0,"Atpaliek no trajektorijas","Nav progresa")))) -> Atpaliek no trajektorijas | G26: ='Rādītāji - vērtības'!M47 -> 0.067 | H26: =IF(OR(G26="",J26="",K26=""),"",(G26-J26)/(K26-J26)) -> 0.24545455 | I26: Rādītājs 3009. | J26: 0.04 | K26: 0.15 | L26: =IFERROR(($B$40-VALUE(LEFT(E26,4)))/($B$41-VALUE(LEFT(E26,4))),$B$43) -> 0.54545455
A27: Transports
A28: Palielināt AER īpatsvaru sabiedriskā transporta sektorā | B28: 50% | C28: 2030 | D28: 16% | E28: 2019 | F28: =IF(H28="","Nav datu",IF(H28>=1,"Sasniegts",IF(H28>=L28-$B$45,"Atbilst trajektorijai",IF(H28>0,"Atpaliek no trajektorijas","Nav progresa")))) -> Atbilst trajektorijai | G28: ='Rādītāji - vērtības'!M62 -> 0.35446547 | H28: =IF(OR(G28="",J28="",K28=""),"",(G28-J28)/(K28-J28)) -> 0.57195726 | I28: Rādītājs 4007. | J28: 0.16 | K28: 0.5 | L28: =IFERROR(($B$40-VALUE(LEFT(E28,4)))/($B$41-VALUE(LEFT(E28,4))),$B$43) -> 0.54545455
A29: Samazināt privāto automašīnu lietotāju īpatsvaru | B29: 37,4% | C29: 2030 | D29: 42,4% | E29: 2019 | F29: =IF(H29="","Nav datu",IF(H29>=1,"Sasniegts",IF(H29>=L29-$B$45,"Atbilst trajektorijai",IF(H29>0,"Atpaliek no trajektorijas","Nav progresa")))) -> Nav datu | H29: =IF(OR(G29="",J29="",K29=""),"",(G29-J29)/(K29-J29)) | I29: Nav rādītāja (nepieciešams mobilitātes pētījums). | L29: =IFERROR(($B$40-VALUE(LEFT(E29,4)))/($B$41-VALUE(LEFT(E29,4))),$B$43) -> 0.54545455
A32: 4.2. tabula: CO2 samazināšanas mērķi Rīgas pilsētai līdz 2030. gadam
A33: Mērķis | B33: Mērķa vērtība | C33: Mērķa gads | D33: Bāzes vērtība | E33: Bāzes gads | F33: Vidusposma statuss - 2025. gads | G33: 2025. gada vērtība | H33: Progress līdz mērķim | I33: Rādītājs / komentārs | J33: Bāze (aprēķinam) | K33: Mērķis (aprēķinam) | L33: Laika progress (aprēķinam)
A34: Samazināt Rīgas kopējās CO2 emisijas | B34: -30% -70% | C34: 2030 | D34: 1742 ktCO2 4291 ktCO2 | E34: 2019 1990 | F34: =IF(H34="","Nav datu",IF(H34>=1,"Sasniegts",IF(H34>=L34-$B$45,"Atbilst trajektorijai",IF(H34>0,"Atpaliek no trajektorijas","Nav progresa")))) -> Atpaliek no trajektorijas | G34: ='Rādītāji - vērtības'!M70 -> -0.096442111 | H34: =IF(OR(G34="",J34="",K34=""),"",(G34-J34)/(K34-J34)) -> 0.3214737 | I34: ="Pret 2019. g.: "&SUBSTITUTE(TEXT(G34,"+0.0%;-0.0%"),".",",")&" (mērķis -30%). Pret 1990. g.: "&SUBSTITUTE(TEXT('Rādītāji - vērtības'!M69,"+0.0%;-0.0%"),".",",")&" (mērķis -70%). Rādītāji 5002–5003." -> Pret 2019. g.: -9,6% (mērķis -30%). Pret 1990. g.: -63,3% (mērķis -70%). Rādītāji 5002–5003. | J34: 0 | K34: -0.3 | L34: =IFERROR(($B$40-VALUE(LEFT(E34,4)))/($B$41-VALUE(LEFT(E34,4))),$B$43) -> 0.54545455
A35: Samazināt CO2 emisijas enerģijas ražošanā | B35: -30% -51% | C35: 2030 | D35: 934 ktCO2* 1400 ktCO2 | E35: 2019 1990 | F35: =IF(H35="","Nav datu",IF(H35>=1,"Sasniegts",IF(H35>=L35-$B$45,"Atbilst trajektorijai",IF(H35>0,"Atpaliek no trajektorijas","Nav progresa")))) -> Atpaliek no trajektorijas | G35: ='Rādītāji - vērtības'!M72 -> -0.12606548 | H35: =IF(OR(G35="",J35="",K35=""),"",(G35-J35)/(K35-J35)) -> 0.42021827 | I35: ="Pret 2019. g.: "&SUBSTITUTE(TEXT(G35,"+0.0%;-0.0%"),".",",")&" (mērķis -30%). Pret 1990. g.: "&SUBSTITUTE(TEXT('Rādītāji - vērtības'!M71,"+0.0%;-0.0%"),".",",")&" (mērķis -51%). *Bāze 2019 = 934 kt pēc SEG inventarizācijas (CSS 386 + elektroenerģija 247 + kurināmais 301 kt); SECAP 4.2. tabulā norādīts 914 kt, kas neatbilst inventarizācijas datiem. Rādītāji 5004–5005." -> Pret 2019. g.: -12,6% (mērķis -30%). Pret 1990. g.: -41,7% (mērķis -51%). *Bāze 2019 = 934 kt pēc SEG inventarizācijas (CSS 386 + elektroenerģija 247 + kurināmais 301 kt); SECAP 4.2. tabulā norādīts 914 kt, kas neatbilst inventarizācijas datiem. Rādītāji 5004–5005. | J35: 0 | K35: -0.3 | L35: =IFERROR(($B$40-VALUE(LEFT(E35,4)))/($B$41-VALUE(LEFT(E35,4))),$B$43) -> 0.54545455
A36: Samazināt CO2 emisijas transporta sektorā | B36: -30% +21,5% | C36: 2030 | D36: 808 ktCO2* 600 ktCO2 | E36: 2019 1990 | F36: =IF(H36="","Nav datu",IF(H36>=1,"Sasniegts",IF(H36>=L36-$B$45,"Atbilst trajektorijai",IF(H36>0,"Atpaliek no trajektorijas","Nav progresa")))) -> Atpaliek no trajektorijas | G36: ='Rādītāji - vērtības'!M74 -> -0.062199257 | H36: =IF(OR(G36="",J36="",K36=""),"",(G36-J36)/(K36-J36)) -> 0.20733086 | I36: ="Pret 2019. g.: "&SUBSTITUTE(TEXT(G36,"+0.0%;-0.0%"),".",",")&" (mērķis -30%). Pret 1990. g.: "&SUBSTITUTE(TEXT('Rādītāji - vērtības'!M73,"+0.0%;-0.0%"),".",",")&" (pieļaujams +21,5%). *Bāze 2019 = 808 kt pēc SEG inventarizācijas (2019. g. dati no iepriekšējā rīcības plāna monitoringa ziņojuma); SECAP 4.2. tabulā norādīts 729 kt. Rādītāji 5006–5007." -> Pret 2019. g.: -6,2% (mērķis -30%). Pret 1990. g.: +26,3% (pieļaujams +21,5%). *Bāze 2019 = 808 kt pēc SEG inventarizācijas (2019. g. dati no iepriekšējā rīcības plāna monitoringa ziņojuma); SECAP 4.2. tabulā norādīts 729 kt. Rādītāji 5006–5007. | J36: 0 | K36: -0.3 | L36: =IFERROR(($B$40-VALUE(LEFT(E36,4)))/($B$41-VALUE(LEFT(E36,4))),$B$43) -> 0.54545455
A37: Samazināt emisijas Rīgas Domes infrastruktūrā | B37: -100% | C37: 2030 | D37: 37,9 ktCO2 | E37: 2019 | F37: =IF(H37="","Nav datu",IF(H37>=1,"Sasniegts",IF(H37>=L37-$B$45,"Atbilst trajektorijai",IF(H37>0,"Atpaliek no trajektorijas","Nav progresa")))) -> Atpaliek no trajektorijas | G37: ='Rādītāji - vērtības'!M75 -> -0.27310524 | H37: =IF(OR(G37="",J37="",K37=""),"",(G37-J37)/(K37-J37)) -> 0.27310524 | I37: ="Pret 2019. g.: "&SUBSTITUTE(TEXT(G37,"+0.0%;-0.0%"),".",",")&" (mērķis -100%). Rādītājs 5008 (bāze 37,9 kt, ietverot ūdensapgādi)." -> Pret 2019. g.: -27,3% (mērķis -100%). Rādītājs 5008 (bāze 37,9 kt, ietverot ūdensapgādi). | J37: 0 | K37: -1 | L37: =IFERROR(($B$40-VALUE(LEFT(E37,4)))/($B$41-VALUE(LEFT(E37,4))),$B$43) -> 0.54545455
A39: Vērtēšanas metode
A40: Pārskata gads | B40: 2025
A41: Mērķa gads | B41: 2030
A42: Bāzes gads | B42: 2019 | C42: atsevišķos gadījumos 2020
A43: Laika progress (pārskata gads, bāzes gads 2019) | B43: =(B40-B42)/(B41-B42) -> 0.54545455
A44: Progress = (2025. g. vērtība − bāze) / (mērķis − bāze). Laika progress katram mērķim aprēķināts pēc tā bāzes gada (kolonna E; kolonna L): 2019 – 54,5%, 2020 – 50,0%. Statuss: ≥100% – Sasniegts; ≥ laika progress − pielaide – Atbilst trajektorijai; >0 – Atpaliek no trajektorijas; ≤0 – Nav progresa; bez rādītāja – Nav datu.
...

Sheet Rādītāji - vērtības
C6: Nosaukums | D6: Sektors | E6: Apakšsektors | F6: Vienība | H6: 2020 | I6: 2021 | J6: 2022 | K6: 2023 | L6: 2024 | M6: 2025
C7: Pašvaldības sektors
B8: 1001 | C8: Objektu skaits energopārvaldības sistēmā | D8: Pašvaldības infrastruktūra | E8: Ēkas | F8: skaits | J8: 369 | K8: 413 | L8: 432 | M8: 424
B9: 1002 | C9: Enerģijas patēriņš pašvaldības ēkās | D9: Pašvaldības infrastruktūra | E9: Ēkas | F9: MWh/gadā | H9: =SUM(H10:H11) -> 199244 | I9: =SUM(I10:I11) -> 207305 | J9: =SUM(J10:J11) -> 191018 | K9: =SUM(K10:K11) -> 171047 | L9: =SUM(L10:L11) -> 167576 | M9: =SUM(M10:M11) -> 171992
B10: 1003 | C10: Pašvaldības ēku elektroenerģijas patēriņš | D10: Pašvaldības infrastruktūra | E10: Ēkas | F10: MWh/gadā | H10: 33299 | I10: 30282 | J10: 35423 | K10: 33823 | L10: 34478 | M10: 35226
B11: 1004 | C11: Pašvaldības ēku siltumenerģijas patēriņš | D11: Pašvaldības infrastruktūra | E11: Ēkas | F11: MWh/gadā | H11: 165945 | I11: 177023 | J11: 155595 | K11: 137224 | L11: 133098 | M11: 136766
B12: 1005 | C12: Pašvaldības ēku dabasgāzes patēriņš | D12: Pašvaldības infrastruktūra | E12: Ēkas | F12: MWh/gadā | H12: 2418.8126 | I12: 3238.9719 | J12: 3297.6039 | K12: 2672.5751 | L12: 2423.8828 | M12: 2120.0344
B13: 1006 | C13: Īpatnējais siltumenerģijas patēriņš pašvaldības biroju ēkās | D13: Pašvaldības infrastruktūra | E13: Ēkas | F13: kWh/m2 | H13: 89 | I13: 107 | J13: 93 | K13: 82 | L13: 89 | M13: 89
B14: 1007 | C14: Īpatnējais siltumenerģijas patēriņš skolās | D14: Pašvaldības infrastruktūra | E14: Ēkas | F14: kWh/m2 | H14: 117 | I14: 143 | J14: 126 | K14: 113 | L14: 107 | M14: 107
B15: 1008 | C15: Īpatnējais ūdens patēriņš pašvaldības ēkās | D15: Pašvaldības infrastruktūra | E15: Ēkas | F15: l/m2 | H15: 706 | I15: 668 | J15: 720 | K15: 687 | L15: 617 | M15: 569
B16: 1009 | C16: Atjaunoto pašvaldības ēku skaits | D16: Pašvaldības infrastruktūra | E16: Ēkas | F16: skaits, kumulatīvi
B17: 1010 | C17: Uzstādīto saules paneļu jaudas | D17: Pašvaldības infrastruktūra | E17: Ēkas | F17: kWp, kumulatīvi | H17: =21+10.3 -> 31.3 | I17: =H17 -> 31.3 | J17: =I17 -> 31.3 | K17: =J17+50 -> 81.3 | L17: =K17+100+20 -> 201.3 | M17: =L17+135+95+90+88+50 -> 659.3
B18: 1011 | C18: Elektroenerģijas patēriņš ielu apgaismojumam | D18: Pašvaldības infrastruktūra | E18: Ielu apgaismojums | F18: MWh/gadā | H18: 24863 | I18: 23806.6 | J18: 21655.4 | K18: 20635.13 | L18: 21304.2 | M18: 20888.5
B19: 1012 | C19: Īpatnējais enerģijas patēriņš uz gaismekli | D19: Pašvaldības infrastruktūra | E19: Ielu apgaismojums | F19: MWh/gaismeklis gadā | H19: 0.497 | I19: 0.46991966 | J19: 0.42613641 | K19: 0.40088452 | L19: 0.40293917 | M19: 0.39222811
B20: 1013 | C20: LED gaismekļu īpatsvars ielu apgaismojumā | D20: Pašvaldības infrastruktūra | E20: Ielu apgaismojums | F20: % | H20: 0.1111 | I20: 0.1665 | J20: 0.173 | K20: 0.2303 | L20: 0.2665 | M20: 0.2935
B21: 1014 | C21: Elektroauto skaits pašvaldības autoparkā | D21: Pašvaldības infrastruktūra | E21: Transports | F21: skaits | H21: 10 | I21: 43 | J21: 45 | K21: 59 | L21: 119 | M21: 173
B22: 1015 | C22: Elektroauto īpatsvars | D22: Pašvaldības infrastruktūra | E22: Transports | F22: % | H22: =H21/1444 -> 0.0069252078 | I22: =I21/1438 -> 0.029902643 | J22: =J21/1431 -> 0.031446541 | K22: =K21/1411 -> 0.041814316 | L22: =L21/1523 -> 0.078135259 | M22: =M21/1443 -> 0.11988912
B23: 1016 | C23: Pašvaldības ēku elektroenerģijas patēriņa CO2 emisijas | D23: Pašvaldības infrastruktūra | E23: CO2 emisijas | F23: tCO2/gadā | H23: 3630 | I23: 3301 | J23: 3861 | K23: 3687 | L23: 3758 | M23: 3840
B24: 1017 | C24: Pašvaldības ēku siltumenerģijas patēriņa CO2 emisijas | D24: Pašvaldības infrastruktūra | E24: CO2 emisijas | F24: tCO2/gadā | H24: 24062 | I24: 25314 | J24: 21646 | K24: 17839 | L24: 17369 | M24: 16426
B25: 1018 | C25: Ielu apgaismojuma elektroenerģijas patēriņa CO2 emisijas | D25: Pašvaldības infrastruktūra | E25: CO2 emisijas | F25: tCO2/gadā | H25: 2710 | I25: 2595 | J25: 2360 | K25: 2249 | L25: 2322 | M25: 2277
B26: 1019 | C26: Ūdens apgādes elektroenerģijas patēriņa CO2 emisijas | D26: Pašvaldības infrastruktūra | E26: CO2 emisijas | F26: tCO2/gadā | H26: 3840 | I26: 3846 | J26: 3851 | K26: 3802 | L26: 3744 | M26: 3812
B27: 1020 | C27: Pašvaldības sektora transporta CO2 emisijas | D27: Pašvaldības infrastruktūra | E27: CO2 emisijas | F27: tCO2/gadā | H27: 3618 | I27: 4576.9655 | J27: 3817.5073 | K27: 1782.5174 | L27: 1345.9541 | M27: 1194.3112
B28: 1021 | C28: Pašvaldības sektora CO2 emisijas, kopā | D28: Pašvaldības infrastruktūra | E28: CO2 emisijas | F28: tCO2/gadā | H28: =SUM(H23:H27) -> 37860 | I28: =SUM(I23:I27) -> 39632.966 | J28: =SUM(J23:J27) -> 35535.507 | K28: =SUM(K23:K27) -> 29359.517 | L28: =SUM(L23:L27) -> 28538.954 | M28: =SUM(M23:M27) -> 27549.311
C29: Daudzdzīvokļu dzīvojamo ēku sektors
B30: 2001 | C30: Daudzdzīvokļu ēku siltumenerģijas patēriņš, kas pieslēgtas CSS (ar klimata korekciju) | D30: Daudzdzīvokļu ēkas | E30: Siltumapgāde | F30: MWh/gadā | H30: 2455669 | I30: 2387452 | J30: 2300619 | K30: 2243883 | L30: 2309989 | M30: 2245623
B31: 2002 | C31: Energoefektivitātes novērtējums apkurei - visas ēkas, pieslēgtas CSS | D31: Daudzdzīvokļu ēkas | E31: Siltumapgāde | F31: kWh/m2 | H31: 147 | I31: 141.88 | J31: 119.14 | K31: 111.87 | L31: 114.15 | M31: 113.21
B32: 2003 | C32: Energoefektivitātes novērtējums apkurei - atjaunotās ēkas, pieslēgtas CSS | D32: Daudzdzīvokļu ēkas | E32: Siltumapgāde | F32: kWh/m2 | I32: 83.83 | J32: 69.05 | K32: 64.72 | L32: 73.51 | M32: 62.83
B33: 2004 | C33: Atjaunoto daudzdzīvokļu ēku skaits | D33: Daudzdzīvokļu ēkas | E33: Atjaunošana | F33: skaits, kopā | H33: 68 | I33: 71 | J33: 76 | K33: 136 | L33: 146 | M33: 209
B34: 2005 | C34: Daudzdzīvokļu ēku skaits gadā, kas pieteikušās veikt ēku atjaunošanu | D34: Daudzdzīvokļu ēkas | E34: Atjaunošana | F34: skaits, gadā | M34: 44
B35: 2006 | C35: Konsultācijas iedzīvotājiem par ēku atjaunošanu | D35: Daudzdzīvokļu ēkas | E35: Atjaunošana | F35: skaits/gadā | H35: 489 | I35: 307 | J35: 359 | K35: 241 | L35: 334 | M35: 222
B36: 2007 | C36: CO2 emisijas - mājsaimniecību sektors (siltumenerģija un kurināmais) | D36: Daudzdzīvokļu ēkas | E36: CO2 emisijas | F36: tCO2/gadā | H36: 367435 | I36: 469332.48 | J36: 399714.11 | K36: 358054.36 | L36: 364799.52 | M36: 344654.15
B37: 2008 | C37: CO2 emisijas - mājsaimniecību sektors (elektroenerģija) | D37: Daudzdzīvokļu ēkas | E37: CO2 emisijas | F37: tCO2/gadā | H37: 55392 | I37: 57196 | J37: 53545 | K37: 51625 | L37: 52900 | M37: 54282
C38: Enerģijas ražošanas sektors
B39: 3001 | C39: Patērētājiem nodotais siltumenerģijas apjoms Rīgas pilsētas CSS | D39: Enerģija | E39: Siltumapgāde | F39: GWh/gadā | H39: 2756 | I39: 3310.801 | J39: 2904.7761 | K39: 2763.3598 | L39: 2786.17 | M39: 2818.5049
B40: 3002 | C40: AER īpatsvars Rīgas pilsētas CSS | D40: Enerģija | E40: Siltumapgāde | F40: % | H40: 0.31 | I40: 0.3338 | J40: 0.4059 | K40: 0.4133 | L40: 0.4174 | M40: 0.4685
B41: 3003 | C41: Dabasgāzes patēriņš mājokļu sektorā (mājsaimniecības) | D41: Enerģija | E41: Decentralizētā energoapgāde | F41: GWh/gadā | H41: 294.7 | I41: 518.7 | J41: 438.352 | K41: 424.4 | L41: 420 | M41: 415.877
B42: 3004 | C42: Dabasgāzes patēriņš sabiedriskais sektors (pārējie lietotāji) | D42: Enerģija | E42: Decentralizētā energoapgāde | F42: GWh/gadā | H42: 3167 | I42: 3096 | J42: 2077 | K42: 2195 | L42: 2429 | M42: 2101
B43: 3005 | C43: Dabasgāzes patēriņš Rīgā kopā | D43: Enerģija | E43: Dabasgāze | F43: GWh/gadā | H43: 3461 | I43: 3614 | J43: 2515 | K43: 2619 | L43: 2849 | M43: 2516.877
B44: 3006 | C44: Decentralizētās siltumapgādes īpatsvars siltumenerģijas galapatēriņā | D44: Enerģija | E44: Decentralizētā energoapgāde | F44: % | H44: 0.4987 | I44: 0.4594 | J44: 0.4632 | K44: 0.4458 | L44: 0.461 | M44: 0.4272
B45: 3007 | C45: AER īpatsvars decentralizētajā siltumapgādē | D45: Enerģija | E45: Decentralizētā energoapgāde | F45: % | H45: 0.4182 | I45: 0.3463 | J45: 0.426 | K45: 0.3418 | L45: 0.384 | M45: 0.3423
...

Sheet Rādītāji - apraksts metode
C2: Nosaukums | D2: Sektors | E2: Apakšsektors | F2: Vienība | H2: Apraksts | I2: Saite uz resursu, ja pieejama | K2: Citu struktūrvienību iesaiste
C3: Pašvaldības sektors
B4: 1001 | C4: Objektu skaits energopārvaldības sistēmā | D4: Pašvaldības infrastruktūra | E4: Ēkas | F4: skaits | H4: Sistēmas dati par objektu skaitu EPS
B5: 1002 | C5: Enerģijas patēriņš pašvaldības ēkās | D5: Pašvaldības infrastruktūra | E5: Ēkas | F5: MWh/gadā | H5: Dati par kopējo patēriņu - visi objekti, arī ārpus EPS
B6: 1003 | C6: Pašvaldības ēku elektroenerģijas patēriņš | D6: Pašvaldības infrastruktūra | E6: Ēkas | F6: MWh/gadā | H6: Dati par kopējo patēriņu - visi objekti, arī ārpus EPS
B7: 1004 | C7: Pašvaldības ēku siltumenerģijas patēriņš | D7: Pašvaldības infrastruktūra | E7: Ēkas | F7: MWh/gadā | H7: Dati par kopējo patēriņu - visi objekti, arī ārpus EPS
B8: 1005 | C8: Pašvaldības ēku dabasgāzes patēriņš | D8: Pašvaldības infrastruktūra | E8: Ēkas | F8: MWh/gadā | H8: Dati par kopējo patēriņu - visi objekti, arī ārpus EPS
B9: 1006 | C9: Īpatnējais siltumenerģijas patēriņš pašvaldības biroju ēkās | D9: Pašvaldības infrastruktūra | E9: Ēkas | F9: kWh/m2 | H9: Aprēķins atsevišķi biroju ēkām - attiecībā pret platību
B10: 1007 | C10: Īpatnējais siltumenerģijas patēriņš skolās | D10: Pašvaldības infrastruktūra | E10: Ēkas | F10: kWh/m2 | H10: Aprēķins atsevišķi skolām - attiecībā pret platību
B11: 1008 | C11: Īpatnējais ūdens patēriņš pašvaldības ēkās | D11: Pašvaldības infrastruktūra | E11: Ēkas | F11: l/m2 | H11: Kopējais patēriņš - attiecībā pret platību
B12: 1009 | C12: Atjaunoto pašvaldības ēku skaits | D12: Pašvaldības infrastruktūra | E12: Ēkas | F12: skaits, kumulatīvi | H12: Kumulatīvais pašvaldības ēku skaits, kurās veikta energoefektivitātes atjaunošana. ĪD dati; 2020–2025 dati nav pieejami. | K12: ĪD
B13: 1010 | C13: Uzstādīto saules paneļu jaudas | D13: Pašvaldības infrastruktūra | E13: Ēkas | F13: kWp, kumulatīvi | H13: Sistēmas dati EPS
B14: 1011 | C14: Elektroenerģijas patēriņš ielu apgaismojumam | D14: Pašvaldības infrastruktūra | E14: Ielu apgaismojums | F14: MWh/gadā | H14: Sistēmas dati EPS
B15: 1012 | C15: Īpatnējais enerģijas patēriņš uz gaismekli | D15: Pašvaldības infrastruktūra | E15: Ielu apgaismojums | F15: MWh/gaismeklis gadā | H15: Sistēmas dati EPS pret gaismekļu skaitu, iesk. prožektorus
B16: 1013 | C16: LED gaismekļu īpatsvars ielu apgaismojumā | D16: Pašvaldības infrastruktūra | E16: Ielu apgaismojums | F16: % | H16: LED skaits pret kopējo gaismekļu skaitu
B17: 1014 | C17: Elektroauto skaits pašvaldības autoparkā | D17: Pašvaldības infrastruktūra | E17: Transports | F17: skaits | H17: Finanšu departamenta dati par pamatlīdzekļu uzskaiti un degvielas patēriņu | K17: FD
B18: 1015 | C18: Elektroauto īpatsvars | D18: Pašvaldības infrastruktūra | E18: Transports | F18: % | H18: Finanšu departamenta dati par pamatlīdzekļu uzskaiti un degvielas patēriņu | K18: FD
B19: 1016 | C19: Pašvaldības ēku elektroenerģijas patēriņa CO2 emisijas | D19: Pašvaldības infrastruktūra | E19: CO2 emisijas | F19: tCO2/gadā | H19: Elektroenerģijas patēriņš reiz emisiju faktors
B20: 1017 | C20: Pašvaldības ēku siltumenerģijas patēriņa CO2 emisijas | D20: Pašvaldības infrastruktūra | E20: CO2 emisijas | F20: tCO2/gadā | H20: Siltumenerģijas patēriņš (bez dabasgāzes) reiz gada CSS emisiju faktors
B21: 1018 | C21: Ielu apgaismojuma elektroenerģijas patēriņa CO2 emisijas | D21: Pašvaldības infrastruktūra | E21: CO2 emisijas | F21: tCO2/gadā | H21: Elektroenerģijas patēriņš reiz emisiju faktors
B22: 1019 | C22: Ūdens apgādes elektroenerģijas patēriņa CO2 emisijas | D22: Pašvaldības infrastruktūra | E22: CO2 emisijas | F22: tCO2/gadā | H22: Elektroenerģijas patēriņš reiz emisiju faktors
B23: 1020 | C23: Pašvaldības sektora transporta CO2 emisijas | D23: Pašvaldības infrastruktūra | E23: CO2 emisijas | F23: tCO2/gadā | H23: Finanšu departamenta dati par pamatlīdzekļu uzskaiti un degvielas patēriņu ar emisiju faktu | K23: FD
B24: 1021 | C24: Pašvaldības sektora CO2 emisijas, kopā | D24: Pašvaldības infrastruktūra | E24: CO2 emisijas | F24: tCO2/gadā | H24: Kopā - elektroenerģija, siltumenerģija, transports
C25: Daudzdzīvokļu dzīvojamo ēku sektors
B26: 2001 | C26: Daudzdzīvokļu ēku siltumenerģijas patēriņš, kas pieslēgtas CSS (ar klimata korekciju) | D26: Daudzdzīvokļu ēkas | E26: Siltumapgāde | F26: MWh/gadā | H26: Ēkām piegādātais siltumenerģijas apjoms proporcionāli apkures dienu skaitam
B27: 2002 | C27: Energoefektivitātes novērtējums apkurei - visas ēkas, pieslēgtas CSS | D27: Daudzdzīvokļu ēkas | E27: Siltumapgāde | F27: kWh/m2 | H27: Vidējais īpatnējais siltumenerģijas patēriņš apkurei visās CSS pieslēgtajās daudzdzīvokļu ēkās – apkures patēriņš (ar klimata korekciju) pret apkurināmo platību.
B28: 2003 | C28: Energoefektivitātes novērtējums apkurei - atjaunotās ēkas, pieslēgtas CSS | D28: Daudzdzīvokļu ēkas | E28: Siltumapgāde | F28: kWh/m2 | H28: Vidējais īpatnējais siltumenerģijas patēriņš apkurei atjaunotajās CSS pieslēgtajās daudzdzīvokļu ēkās – apkures patēriņš (ar klimata korekciju) pret apkurināmo platību.
B29: 2004 | C29: Atjaunoto daudzdzīvokļu ēku skaits | D29: Daudzdzīvokļu ēkas | E29: Atjaunošana | F29: skaits, kopā | H29: Divi avoti: ĢeoRīga CSS pieslēgtās, Ekonomikas ministrijas karte
B30: 2005 | C30: Daudzdzīvokļu ēku skaits gadā, kas pieteikušās veikt ēku atjaunošanu | D30: Daudzdzīvokļu ēkas | E30: Atjaunošana | F30: skaits, gadā | H30: Altum programmas publiskie dati
B31: 2006 | C31: Konsultācijas iedzīvotājiem par ēku atjaunošanu | D31: Daudzdzīvokļu ēkas | E31: Atjaunošana | F31: skaits/gadā | H31: REA ēku grupas konsultāciju reģistrs
B32: 2007 | C32: CO2 emisijas - mājsaimniecību sektors (siltumenerģija un kurināmais) | D32: Daudzdzīvokļu ēkas | E32: CO2 emisijas | F32: tCO2/gadā | H32: SEG aprēķinu tabula - dalījums patēriņa gala sektoros
B33: 2008 | C33: CO2 emisijas - mājsaimniecību sektors (elektroenerģija) | D33: Daudzdzīvokļu ēkas | E33: CO2 emisijas | F33: tCO2/gadā | H33: SEG aprēķinu tabula - dalījums patēriņa gala sektoros
C34: Enerģijas ražošanas sektors
B35: 3001 | C35: Patērētājiem nodotais siltumenerģijas apjoms Rīgas pilsētas CSS | D35: Enerģija | E35: Siltumapgāde | F35: GWh/gadā | H35: Rīgas Siltums dati
B36: 3002 | C36: AER īpatsvars Rīgas pilsētas CSS | D36: Enerģija | E36: Siltumapgāde | F36: % | H36: Rīgas Siltums dati
B37: 3003 | C37: Dabasgāzes patēriņš mājokļu sektorā (mājsaimniecības) | D37: Enerģija | E37: Decentralizētā energoapgāde | F37: GWh/gadā | H37: Gaso dati
B38: 3004 | C38: Dabasgāzes patēriņš sabiedriskais sektors (pārējie lietotāji) | D38: Enerģija | E38: Decentralizētā energoapgāde | F38: GWh/gadā | H38: Gaso dati
B39: 3005 | C39: Dabasgāzes patēriņš Rīgā kopā | D39: Enerģija | E39: Dabasgāze | F39: GWh/gadā | H39: Gaso dati
B40: 3006 | C40: Decentralizētās siltumapgādes īpatsvars siltumenerģijas galapatēriņā | D40: Enerģija | E40: Decentralizētā energoapgāde | F40: % | H40: SEG inventarizācija (Riga-CO2-Kopa-2025): decentralizētā kurināmā patēriņš / kopējais siltumenerģijas galapatēriņš (CSS + decentralizētā), Kopā_2025 rinda 67 / rinda 24. Ietver ETS iekārtas un GASO “pārējos” patērētājus.
B41: 3007 | C41: AER īpatsvars decentralizētajā siltumapgādē | D41: Enerģija | E41: Decentralizētā energoapgāde | F41: % | H41: SEG inventarizācija (Riga-CO2-Kopa-2025): (biomasa decentralizētajā apgādē pēc CSS atskaitīšanas, Decentralizēti_2020–2025 lapas + mājsaimniecību AER ārpus CSS) / decentralizētā kurināmā patēriņš (Kopā_2025 rinda 67). Mājsaimniecību AER = rinda 17 − dabasgāze (GASO).
...
